Workbook

Sheet README
C2: Alphabet valuation teaching model
C4: Case selected | D4: =CHOOSE(Assumptions!$D$4,"Base","Bull","Bear") -> Base
C6: USD millions, except per-share values. Financials through June 30, 2026; valuation October 17, 2026.
C8: Prices are October 16 closes from Google Finance. Exchange-direct verification was unavailable.
C10: Blue = sourced numeric input. Yellow = editable key driver. Black = formula. Green = cross-sheet formula.
C12: One forecast build responds to the Base / Bull / Bear selector in Assumptions!D4.
C14: Low / active / high DCF values are discount-rate and growth bounds for the selected operating case.
C16: SBC stays in EBIT and is never added back. D&A and capex are modeled separately.
C18: The stub uses the remaining share of projected H2 cash flow; annual flows use mid-year discounting.
C20: Terminal capex is normalized to D&A × the editable ratio. This dominates value and is not guidance.
C22: Search, YouTube, Network and subscriptions EBIT margins are allocations, not disclosed segment profits.
C24: Cash bridge uses June 30 balances with no July–October roll-forward. Equity stakes are treated explicitly.
C26: Preferred stock is deducted at liquidation preference; conversion and capped calls are not option-priced.
C28: Non-marketable investments are excluded in Base. Deferred tax and accrued legal claims are deducted.
... C104: https://data.sec.gov/api/xbrl/companyfacts/CIK0001018724.json

Sheet Assumptions
C2: Assumptions
C4: Case selected | D4: 1 | F4: =CHOOSE(D4,"Base","Bull","Bear") -> Base | J4: 1 Base / 2 Bull / 3 Bear. Change only this selector.
C6: Valuation date | D6: 46312 | J6: User requested date, America/Los_Angeles
C7: GOOGL closing price | D7: 340.59 | J7: Q1: October 16, 2026 close. Vendor quote, not exchange-direct.
C8: Quote date | D8: 46311 | J8: Q1: last trading close before valuation date
C9: Risk-free rate assumption | D9: 0.045 | J9: A1: rounded teaching assumption, not a verified current Treasury yield.
C10: Beta assumption | D10: 1.2 | J10: A1: teaching beta, not a regression estimate.
C11: Equity risk premium assumption | D11: 0.045 | J11: A1: teaching ERP, not a market fact.
C12: Pre-tax cost of debt proxy | D12: 0.048 | J12: S2 Note 6: Q1 USD issue weighted coupon 4.80%; current yield may differ.
C13: Normalized tax rate | D13: 0.2 | J13: A1: operating tax assumption; H1 GAAP tax includes investment gains.
C14: Terminal growth | D14: 0.03 | J14: A1: perpetual nominal growth, independent of forecast growth.
C15: Terminal capex / D&A | D15: 1.15 | J15: A1: capex exceeds D&A by 15% in steady state; normalized after AI buildout.
C16: Non-marketable stake realization | D16: 0 | J16: A1: exclude unlisted investments; no double count of marketable securities.
C17: 2026 capex guide low | D17: 195000 | J17: S3: July 22, 2026 CFO guidance, USD millions.
C18: 2026 capex guide high | D18: 205000 | J18: S3: July 22, 2026 CFO guidance, USD millions.
C19: 2026 capex guidance midpoint | D19: =AVERAGE(D17:D18) -> 200000
C20: Preferred cost proxy | D20: 0.0625 | J20: S2 Note 11: coupon rate, used as market yield proxy.
C21: WACC sensitivity step | D21: 0.005 | J21: A1: 0.5 percentage point grid interval.
C22: Growth sensitivity step | D22: 0.005 | J22: A1: 0.5 percentage point grid interval.
C23: Forecast hedging gain assumption | D23: 0 | J23: A1: no forecast gains/losses; known H1 actual remains in 2026.
C26: Forecast drivers | D26: 2026E | E26: 2027E | F26: 2028E | G26: 2029E | H26: 2030E | J26: 2026 revenue driver applies to H2 2025 comparable; later years apply to full year.
C28: Search growth — active | D28: =IF(ISNUMBER(CHOOSE($D$4,D29,D30,D31)),CHOOSE($D$4,D29,D30,D31),"Missing input") -> 0.16 | E28: =IF(ISNUMBER(CHOOSE($D$4,E29,E30,E31)),CHOOSE($D$4,E29,E30,E31),"Missing input") -> 0.12 | F28: =IF(ISNUMBER(CHOOSE($D$4,F29,F30,F31)),CHOOSE($D$4,F29,F30,F31),"Missing input") -> 0.1 | G28: =IF(ISNUMBER(CHOOSE($D$4,G29,G30,G31)),CHOOSE($D$4,G29,G30,G31),"Missing input") -> 0.08 | H28: =IF(ISNUMBER(CHOOSE($D$4,H29,H30,H31)),CHOOSE($D$4,H29,H30,H31),"Missing input") -> 0.07 | J28: A1 / S2: H1 Search grew 17.9%; gradual moderation.
C29: Base | D29: 0.16 | E29: 0.12 | F29: 0.1 | G29: 0.08 | H29: 0.07 | J29: A1 / S2: H1 Search grew 17.9%; gradual moderation.
C30: Bull | D30: 0.19 | E30: 0.15 | F30: 0.13 | G30: 0.11 | H30: 0.09 | J30: A1 / S2: H1 Search grew 17.9%; gradual moderation.
C31: Bear | D31: 0.1 | E31: 0.08 | F31: 0.06 | G31: 0.05 | H31: 0.04 | J31: A1 / S2: H1 Search grew 17.9%; gradual moderation.
C33: YouTube growth — active | D33: =IF(ISNUMBER(CHOOSE($D$4,D34,D35,D36)),CHOOSE($D$4,D34,D35,D36),"Missing input") -> 0.13 | E33: =IF(ISNUMBER(CHOOSE($D$4,E34,E35,E36)),CHOOSE($D$4,E34,E35,E36),"Missing input") -> 0.12 | F33: =IF(ISNUMBER(CHOOSE($D$4,F34,F35,F36)),CHOOSE($D$4,F34,F35,F36),"Missing input") -> 0.11 | G33: =IF(ISNUMBER(CHOOSE($D$4,G34,G35,G36)),CHOOSE($D$4,G34,G35,G36),"Missing input") -> 0.1 | H33: =IF(ISNUMBER(CHOOSE($D$4,H34,H35,H36)),CHOOSE($D$4,H34,H35,H36),"Missing input") -> 0.09 | J33: A1 / S2: H1 YouTube grew 11.8%; World Cup timing.
C34: Base | D34: 0.13 | E34: 0.12 | F34: 0.11 | G34: 0.1 | H34: 0.09 | J34: A1 / S2: H1 YouTube grew 11.8%; World Cup timing.
C35: Bull | D35: 0.16 | E35: 0.15 | F35: 0.14 | G35: 0.12 | H35: 0.1 | J35: A1 / S2: H1 YouTube grew 11.8%; World Cup timing.
C36: Bear | D36: 0.08 | E36: 0.07 | F36: 0.06 | G36: 0.05 | H36: 0.05 | J36: A1 / S2: H1 YouTube grew 11.8%; World Cup timing.
C38: Network growth — active | D38: =IF(ISNUMBER(CHOOSE($D$4,D39,D40,D41)),CHOOSE($D$4,D39,D40,D41),"Missing input") -> -0.02 | E38: =IF(ISNUMBER(CHOOSE($D$4,E39,E40,E41)),CHOOSE($D$4,E39,E40,E41),"Missing input") -> -0.02 | F38: =IF(ISNUMBER(CHOOSE($D$4,F39,F40,F41)),CHOOSE($D$4,F39,F40,F41),"Missing input") -> -0.01 | G38: =IF(ISNUMBER(CHOOSE($D$4,G39,G40,G41)),CHOOSE($D$4,G39,G40,G41),"Missing input") -> 0 | H38: =IF(ISNUMBER(CHOOSE($D$4,H39,H40,H41)),CHOOSE($D$4,H39,H40,H41),"Missing input") -> 0 | J38: A1 / S2: H1 Network contracted 2.3%.
C39: Base | D39: -0.02 | E39: -0.02 | F39: -0.01 | G39: 0 | H39: 0 | J39: A1 / S2: H1 Network contracted 2.3%.
C40: Bull | D40: 0 | E40: 0.01 | F40: 0.01 | G40: 0.01 | H40: 0.01 | J40: A1 / S2: H1 Network contracted 2.3%.
C41: Bear | D41: -0.05 | E41: -0.05 | F41: -0.04 | G41: -0.03 | H41: -0.02 | J41: A1 / S2: H1 Network contracted 2.3%.
C43: Subscriptions & devices growth — active | D43: =IF(ISNUMBER(CHOOSE($D$4,D44,D45,D46)),CHOOSE($D$4,D44,D45,D46),"Missing input") -> 0.16 | E43: =IF(ISNUMBER(CHOOSE($D$4,E44,E45,E46)),CHOOSE($D$4,E44,E45,E46),"Missing input") -> 0.15 | F43: =IF(ISNUMBER(CHOOSE($D$4,F44,F45,F46)),CHOOSE($D$4,F44,F45,F46),"Missing input") -> 0.13 | G43: =IF(ISNUMBER(CHOOSE($D$4,G44,G45,G46)),CHOOSE($D$4,G44,G45,G46),"Missing input") -> 0.12 | H43: =IF(ISNUMBER(CHOOSE($D$4,H44,H45,H46)),CHOOSE($D$4,H44,H45,H46),"Missing input") -> 0.1 | J43: A1 / S2: H1 subscriptions/platforms/devices grew 17.2%.
C44: Base | D44: 0.16 | E44: 0.15 | F44: 0.13 | G44: 0.12 | H44: 0.1 | J44: A1 / S2: H1 subscriptions/platforms/devices grew 17.2%.
C45: Bull | D45: 0.2 | E45: 0.18 | F45: 0.16 | G45: 0.14 | H45: 0.12 | J45: A1 / S2: H1 subscriptions/platforms/devices grew 17.2%.
C46: Bear | D46: 0.1 | E46: 0.09 | F46: 0.08 | G46: 0.07 | H46: 0.06 | J46: A1 / S2: H1 subscriptions/platforms/devices grew 17.2%.
C48: Cloud growth — active | D48: =IF(ISNUMBER(CHOOSE($D$4,D49,D50,D51)),CHOOSE($D$4,D49,D50,D51),"Missing input") -> 0.7 | E48: =IF(ISNUMBER(CHOOSE($D$4,E49,E50,E51)),CHOOSE($D$4,E49,E50,E51),"Missing input") -> 0.5 | F48: =IF(ISNUMBER(CHOOSE($D$4,F49,F50,F51)),CHOOSE($D$4,F49,F50,F51),"Missing input") -> 0.35 | G48: =IF(ISNUMBER(CHOOSE($D$4,G49,G50,G51)),CHOOSE($D$4,G49,G50,G51),"Missing input") -> 0.28 | H48: =IF(ISNUMBER(CHOOSE($D$4,H49,H50,H51)),CHOOSE($D$4,H49,H50,H51),"Missing input") -> 0.22 | J48: A1 / S2 / S3: H1 Cloud +73.1%; $513.9bn backlog, timing uncertain.
C49: Base | D49: 0.7 | E49: 0.5 | F49: 0.35 | G49: 0.28 | H49: 0.22 | J49: A1 / S2 / S3: H1 Cloud +73.1%; $513.9bn backlog, timing uncertain.
C50: Bull | D50: 0.85 | E50: 0.6 | F50: 0.45 | G50: 0.35 | H50: 0.28 | J50: A1 / S2 / S3: H1 Cloud +73.1%; $513.9bn backlog, timing uncertain.
...

Sheet Summary
C2: Summary
C4: Case selected | D4: =CHOOSE(Assumptions!$D$4,"Base","Bull","Bear") -> Base
C6: Valuation date | D6: =Assumptions!D6 -> 46312 | F6: Closing price | G6: =Assumptions!D7 -> 340.59
C8: Value per common share | D8: Low | E8: Active / median | F8: High | G8: Market
C9: DCF | D9: =Sensitivity!E16 -> 158.91956 | E9: =DCF!D51 -> 212.65235 | F9: =Sensitivity!G10 -> 312.30694 | G9: =Assumptions!D7 -> 340.59
C10: P/E (GAAP TTM) | D10: =Multiples!D59 -> 397.75709 | E10: =Multiples!E59 -> 528.72438 | F10: =Multiples!F59 -> 586.40103 | G10: =Assumptions!D7 -> 340.59
C11: EV / Sales | D11: =Multiples!D60 -> 133.90718 | E11: =Multiples!E60 -> 293.83207 | F11: =Multiples!F60 -> 434.43691 | G11: =Assumptions!D7 -> 340.59
C12: EV / EBITD | D12: =Multiples!D61 -> 240.95074 | E12: =Multiples!E61 -> 273.29739 | F12: =Multiples!F61 -> 297.06765 | G12: =Assumptions!D7 -> 340.59
C13: Forward P/E (CY2027 adjusted) | D13: =Multiples!D62 -> 312.36298 | E13: =Multiples!E62 -> 364.83254 | F13: =Multiples!F62 -> 370.9431 | G13: =Assumptions!D7 -> 340.59
C15: Selected-case WACC | D15: =DCF!D15 -> 0.097468734
C16: Terminal growth | D16: =Assumptions!D14 -> 0.03
C17: Terminal value / EV | D17: =DCF!D40 -> 0.9402105
C18: DCF vs closing price | D18: =DCF!D52 -> -0.37563538
C20: 2030 revenue (USD millions) | D20: =Projections!H15 -> 880073.9
C21: 2027 capex intensity | D21: =Assumptions!E83 -> 0.46
C22: 2027 FCF (USD millions) | D22: =Projections!E40 -> -68108.003
C23: Required / modeled terminal FCF | D23: =Sensitivity!D23 -> 1.6609395
C26: DCF bounds: WACC ±1.5 percentage points and growth ±0.5 points, for the selected operating case.
C28: Forward P/E uses CY2027 adjusted consensus, with MSFT calendarized. GAAP P/E includes investment gains.
C30: EV/EBITD = EV / (EBIT + PPE depreciation), using reported inputs. It replaces EBITDA; all intangible amortization remains expensed.

Sheet Historicals
C2: Historicals
C4: Case selected | D4: =CHOOSE(Assumptions!$D$4,"Base","Bull","Bear") -> Base
C6: Reported results | D6: FY2023 | E6: FY2024 | F6: FY2025 | G6: H1 2025 | H6: H1 2026 | J6: S1 annual; S2 interim. USD millions. Interim figures unaudited.
C8: Search & other | D8: 175033 | E8: 198084 | F8: 224532 | G8: 104892 | H8: 123670 | J8: S1 annual; S2 H1. Reported, USD millions except EPS.
C9: YouTube ads | D9: 31510 | E9: 36147 | F9: 40367 | G9: 18723 | H9: 20938 | J9: S1 annual; S2 H1. Reported, USD millions except EPS.
C10: Network | D10: 31312 | E10: 30359 | F10: 29792 | G10: 14610 | H10: 14274 | J10: S1 annual; S2 H1. Reported, USD millions except EPS.
C11: Subscriptions, platforms & devices | D11: 34688 | E11: 40340 | F11: 48030 | G11: 21582 | H11: 25295 | J11: S1 annual; S2 H1. Reported, USD millions except EPS.
C12: Google Cloud | D12: 33088 | E12: 43229 | F12: 58705 | G12: 25884 | H12: 44796 | J12: S1 annual; S2 H1. Reported, USD millions except EPS.
C13: Other Bets | D13: 1527 | E13: 1648 | F13: 1537 | G13: 823 | H13: 793 | J13: S1 annual; S2 H1. Reported, USD millions except EPS.
C14: Hedging gains / (losses) | D14: 236 | E14: 211 | F14: -127 | G14: 148 | H14: -74 | J14: S1 annual; S2 H1. Reported, USD millions except EPS.
C15: Reported revenue | D15: 307394 | E15: 350018 | F15: 402836 | G15: 186662 | H15: 229692 | J15: S1 annual; S2 H1. Reported, USD millions except EPS.
C16: Revenue reconciliation difference | D16: =SUM(D8:D14)-D15 -> 0 | E16: =SUM(E8:E14)-E15 -> 0 | F16: =SUM(F8:F14)-F15 -> 0 | G16: =SUM(G8:G14)-G15 -> 0 | H16: =SUM(H8:H14)-H15 -> 0
C18: Cost of revenue | D18: 133332 | E18: 146306 | F18: 162535 | G18: 75400 | H18: 87214 | J18: S1 annual; S2 H1. Reported, USD millions except EPS.
C19: Research & development | D19: 45427 | E19: 49326 | F19: 61087 | G19: 27364 | H19: 35251 | J19: S1 annual; S2 H1. Reported, USD millions except EPS.
C20: Sales & marketing | D20: 27917 | E20: 27808 | F20: 28693 | G20: 13273 | H20: 16009 | J20: S1 annual; S2 H1. Reported, USD millions except EPS.
C21: General & administrative | D21: 16425 | E21: 14188 | F21: 21482 | G21: 8748 | H21: 10752 | J21: S1 annual; S2 H1. Reported, USD millions except EPS.
C22: Reported operating income | D22: 84293 | E22: 112390 | F22: 129039 | G22: 61877 | H22: 80466 | J22: S1 annual; S2 H1. Reported, USD millions except EPS.
C23: Computed operating income | D23: =D15-SUM(D18:D21) -> 84293 | E23: =E15-SUM(E18:E21) -> 112390 | F23: =F15-SUM(F18:F21) -> 129039 | G23: =G15-SUM(G18:G21) -> 61877 | H23: =H15-SUM(H18:H21) -> 80466
C24: Operating income difference | D24: =D23-D22 -> 0 | E24: =E23-E22 -> 0 | F24: =F23-F22 -> 0 | G24: =G23-G22 -> 0 | H24: =H23-H22 -> 0
C25: Income before tax | D25: 85717 | E25: 119815 | F25: 158826 | G25: 75722 | H25: 216165 | J25: S1 annual; S2 H1. Reported, USD millions except EPS.
C26: Income tax provision | D26: 11922 | E26: 19697 | F26: 26656 | G26: 12986 | H26: 41394 | J26: S1 annual; S2 H1. Reported, USD millions except EPS.
C27: Net income | D27: 73795 | E27: 100118 | F27: 132170 | G27: 62736 | H27: 174771 | J27: S1 annual; S2 H1. Reported, USD millions except EPS.
C28: Net income available to common | D28: 73795 | E28: 100118 | F28: 132170 | G28: 62736 | H28: 174685 | J28: S1 annual; S2 H1. Reported, USD millions except EPS.
C29: Diluted EPS | D29: 5.8 | E29: 8.04 | F29: 10.81 | G29: 5.12 | H29: 14.24 | J29: S1 annual; S2 H1. Reported, USD millions except EPS.
C30: PPE depreciation | D30: 11946 | E30: 15311 | F30: 21136 | G30: 9485 | H30: 13586 | J30: S1 annual; S2 H1. Reported, USD millions except EPS.
C31: Stock-based compensation | D31: 22460 | E31: 22785 | F31: 24953 | G31: 11514 | H31: 14708 | J31: S1 annual; S2 H1. Reported, USD millions except EPS.
C32: Cash from operations | D32: 101746 | E32: 125299 | F32: 164713 | G32: 63897 | H32: 84859 | J32: S1 annual; S2 H1. Reported, USD millions except EPS.
C33: Purchases of PPE (positive outflow) | D33: 32251 | E33: 52535 | F33: 91447 | G33: 39643 | H33: 80598 | J33: S1 annual; S2 H1. Reported, USD millions except EPS.
C34: Computed operating cash flow less capex | D34: =D32-D33 -> 69495 | E34: =E32-E33 -> 72764 | F34: =F32-F33 -> 73266 | G34: =G32-G33 -> 24254 | H34: =H32-H33 -> 4261
C36: Accounts receivable | F36: 62886 | H36: 69175 | J36: S2 balance sheet / notes; point in time. Blank = not collected.
C37: Inventory | F37: 2439 | H37: 9991 | J37: S2 balance sheet / notes; point in time. Blank = not collected.
C38: Accounts payable | F38: 12200 | H38: 20258 | J38: S2 balance sheet / notes; point in time. Blank = not collected.
C39: Deferred revenue, current | F39: 6578 | H39: 7154 | J39: S2 balance sheet / notes; point in time. Blank = not collected.
C40: Computed trade NWC (AR + inventory − AP − deferred revenue) | F40: =SUM(F36:F37)-SUM(F38:F39) -> 46547 | H40: =SUM(H36:H37)-SUM(H38:H39) -> 51754
C42: Cash, equivalents & marketable securities | F42: 126843 | H42: 242474 | J42: S2 balance sheet / notes; point in time. Blank = not collected.
C43: Long-term debt, carrying value | F43: 46547 | H43: 98165 | J43: S2 balance sheet / notes; point in time. Blank = not collected.
C44: Current portion of notes | F44: 1996 | H44: 1999 | J44: S2 balance sheet / notes; point in time. Blank = not collected.
C45: Fair value of notes | F45: 45600 | H45: 94900 | J45: S2 balance sheet / notes; point in time. Blank = not collected.
C46: Other long-term debt, face value | F46: 0 | H46: 1686 | J46: S2 balance sheet / notes; point in time. Blank = not collected.
C47: Common shares outstanding (all classes) | F47: 12088 | H47: 12230 | J47: S2 balance sheet / notes; point in time. Blank = not collected.
...

Sheet Projections
C2: Projections
C4: Case selected | D4: =CHOOSE(Assumptions!$D$4,"Base","Bull","Bear") -> Base
C6: USD millions | D6: 2026E | E6: 2027E | F6: 2028E | G6: 2029E | H6: 2030E
C8: Search & other | D8: =Historicals!H8+(Historicals!F8-Historicals!G8)*(1+Assumptions!D28) -> 262452.4 | E8: =D8*(1+Assumptions!E28) -> 293946.69 | F8: =E8*(1+Assumptions!F28) -> 323341.36 | G8: =F8*(1+Assumptions!G28) -> 349208.67 | H8: =G8*(1+Assumptions!H28) -> 373653.27
C9: YouTube ads | D9: =Historicals!H9+(Historicals!F9-Historicals!G9)*(1+Assumptions!D33) -> 45395.72 | E9: =D9*(1+Assumptions!E33) -> 50843.206 | F9: =E9*(1+Assumptions!F33) -> 56435.959 | G9: =F9*(1+Assumptions!G33) -> 62079.555 | H9: =G9*(1+Assumptions!H33) -> 67666.715
C10: Network | D10: =Historicals!H10+(Historicals!F10-Historicals!G10)*(1+Assumptions!D38) -> 29152.36 | E10: =D10*(1+Assumptions!E38) -> 28569.313 | F10: =E10*(1+Assumptions!F38) -> 28283.62 | G10: =F10*(1+Assumptions!G38) -> 28283.62 | H10: =G10*(1+Assumptions!H38) -> 28283.62
C11: Subscriptions & devices | D11: =Historicals!H11+(Historicals!F11-Historicals!G11)*(1+Assumptions!D43) -> 55974.68 | E11: =D11*(1+Assumptions!E43) -> 64370.882 | F11: =E11*(1+Assumptions!F43) -> 72739.097 | G11: =F11*(1+Assumptions!G43) -> 81467.788 | H11: =G11*(1+Assumptions!H43) -> 89614.567
C12: Google Cloud | D12: =Historicals!H12+(Historicals!F12-Historicals!G12)*(1+Assumptions!D48) -> 100591.7 | E12: =D12*(1+Assumptions!E48) -> 150887.55 | F12: =E12*(1+Assumptions!F48) -> 203698.19 | G12: =F12*(1+Assumptions!G48) -> 260733.69 | H12: =G12*(1+Assumptions!H48) -> 318095.1
C13: Other Bets | D13: =Historicals!H13+(Historicals!F13-Historicals!G13)*(1+Assumptions!D53) -> 1578.4 | E13: =D13*(1+Assumptions!E53) -> 1815.16 | F13: =E13*(1+Assumptions!F53) -> 2087.434 | G13: =F13*(1+Assumptions!G53) -> 2400.5491 | H13: =G13*(1+Assumptions!H53) -> 2760.6315
C14: Hedging gains / (losses) | D14: =Historicals!H14+Assumptions!$D$23 -> -74 | E14: =Assumptions!$D$23 -> 0 | F14: =Assumptions!$D$23 -> 0 | G14: =Assumptions!$D$23 -> 0 | H14: =Assumptions!$D$23 -> 0
C15: Total revenue | D15: =SUM(D8:D14) -> 495071.26 | E15: =SUM(E8:E14) -> 590432.8 | F15: =SUM(F8:F14) -> 686585.66 | G15: =SUM(G8:G14) -> 784173.86 | H15: =SUM(H8:H14) -> 880073.9
C19: Search & other EBIT | D19: =D8*Assumptions!D58 -> 107605.48 | E19: =E8*Assumptions!E58 -> 120518.14 | F19: =F8*Assumptions!F58 -> 135803.37 | G19: =G8*Assumptions!G58 -> 146667.64 | H19: =H8*Assumptions!H58 -> 156934.37
C20: YouTube ads EBIT | D20: =D9*Assumptions!D58 -> 18612.245 | E20: =E9*Assumptions!E58 -> 20845.715 | F20: =F9*Assumptions!F58 -> 23703.103 | G20: =G9*Assumptions!G58 -> 26073.413 | H20: =H9*Assumptions!H58 -> 28420.02
C21: Network EBIT | D21: =D10*Assumptions!D58 -> 11952.468 | E21: =E10*Assumptions!E58 -> 11713.418 | F21: =F10*Assumptions!F58 -> 11879.12 | G21: =G10*Assumptions!G58 -> 11879.12 | H21: =H10*Assumptions!H58 -> 11879.12
C22: Subscriptions & devices EBIT | D22: =D11*Assumptions!D58 -> 22949.619 | E22: =E11*Assumptions!E58 -> 26392.062 | F22: =F11*Assumptions!F58 -> 30550.421 | G22: =G11*Assumptions!G58 -> 34216.471 | H22: =H11*Assumptions!H58 -> 37638.118
C23: Google Cloud EBIT | D23: =D12*Assumptions!D63 -> 34201.178 | E23: =E12*Assumptions!E63 -> 49792.891 | F23: =F12*Assumptions!F63 -> 69257.385 | G23: =G12*Assumptions!G63 -> 91256.79 | H23: =H12*Assumptions!H63 -> 114514.24
C24: Other Bets EBIT | D24: =D13*Assumptions!D68 -> -7102.8 | E24: =E13*Assumptions!E68 -> -7260.64 | F24: =F13*Assumptions!F68 -> -6262.302 | G24: =G13*Assumptions!G68 -> -4801.0982 | H24: =H13*Assumptions!H68 -> -2760.6315
C25: Alphabet-level costs | D25: =-D15*Assumptions!D73 -> -24753.563 | E25: =-E15*Assumptions!E73 -> -29521.64 | F25: =-F15*Assumptions!F73 -> -30896.355 | G25: =-G15*Assumptions!G73 -> -31366.955 | H25: =-H15*Assumptions!H73 -> -35202.956
C26: Operating income | D26: =SUM(D19:D25) -> 163464.63 | E26: =SUM(E19:E25) -> 192479.95 | F26: =SUM(F19:F25) -> 234034.74 | G26: =SUM(G19:G25) -> 273925.38 | H26: =SUM(H19:H25) -> 311422.28
C27: Operating margin | D27: =D26/D15 -> 0.33018404 | E27: =E26/E15 -> 0.32599806 | F27: =F26/F15 -> 0.34086751 | G27: =G26/G15 -> 0.34931715 | H27: =H26/H15 -> 0.35385924
C29: Normalized operating tax | D29: =D26*Assumptions!$D$13 -> 32692.926 | E29: =E26*Assumptions!$D$13 -> 38495.99 | F29: =F26*Assumptions!$D$13 -> 46806.948 | G29: =G26*Assumptions!$D$13 -> 54785.076 | H29: =H26*Assumptions!$D$13 -> 62284.456
C30: NOPAT | D30: =D26-D29 -> 130771.7 | E30: =E26-E29 -> 153983.96 | F30: =F26-F29 -> 187227.79 | G30: =G26-G29 -> 219140.31 | H30: =H26-H29 -> 249137.82
C32: D&A | D32: =D15*Assumptions!D78 -> 34654.988 | E32: =E15*Assumptions!E78 -> 59043.28 | F32: =F15*Assumptions!F78 -> 82390.279 | G32: =G15*Assumptions!G78 -> 101942.6 | H32: =H15*Assumptions!H78 -> 114409.61
C33: Cash capex | D33: =Assumptions!$D$19 -> 200000 | E33: =E15*Assumptions!E83 -> 271599.09 | F33: =F15*Assumptions!F83 -> 247170.84 | G33: =G15*Assumptions!G83 -> 203885.2 | H33: =H15*Assumptions!H83 -> 167214.04
C34: Capex / revenue | D34: =D33/D15 -> 0.40398225 | E34: =E33/E15 -> 0.46 | F34: =F33/F15 -> 0.36 | G34: =G33/G15 -> 0.26 | H34: =H33/H15 -> 0.19
C36: Ending trade NWC | D36: =D15*Assumptions!D88 -> 49507.126 | E36: =E15*Assumptions!E88 -> 59043.28 | F36: =F15*Assumptions!F88 -> 68658.566 | G36: =G15*Assumptions!G88 -> 78417.386 | H36: =H15*Assumptions!H88 -> 88007.39
C37: Beginning trade NWC | D37: =Historicals!F40 -> 46547 | E37: =D36 -> 49507.126 | F37: =E36 -> 59043.28 | G37: =F36 -> 68658.566 | H37: =G36 -> 78417.386
C38: Change in trade NWC | D38: =D36-D37 -> 2960.126 | E38: =E36-E37 -> 9536.1539 | F38: =F36-F37 -> 9615.286 | G38: =G36-G37 -> 9758.8205 | H38: =H36-H37 -> 9590.0039
C40: Unlevered free cash flow | D40: =D30+D32-D33-D38 -> -37533.433 | E40: =E30+E32-E33-E38 -> -68108.003 | F40: =F30+F32-F33-F38 -> 12831.95 | G40: =G30+G32-G33-G38 -> 107438.88 | H40: =H30+H32-H33-H38 -> 186743.39
C41: EBITDA (forecast) | D41: =D26+D32 -> 198119.62 | E41: =E26+E32 -> 251523.23 | F41: =F26+F32 -> 316425.02 | G41: =G26+G32 -> 375867.98 | H41: =H26+H32 -> 425831.89
C43: D&A and capex allocations are teaching assumptions. The capex test holds revenue and D&A drivers fixed.
C46: Search & other cash-flow allocation
C47: Revenue allocation weight | D47: =D8/SUM(D$8:D$13) -> 0.53005132 | E47: =E8/SUM(E$8:E$13) -> 0.49784952 | F47: =F8/SUM(F$8:F$13) -> 0.47094103 | G47: =G8/SUM(G$8:G$13) -> 0.44532046 | H47: =H8/SUM(H$8:H$13) -> 0.42457034
C48: Allocated D&A | D48: =D$32*D47 -> 18368.922 | E48: =E$32*E47 -> 29394.669 | F48: =F$32*F47 -> 38800.963 | G48: =G$32*G47 -> 45397.126 | H48: =H$32*H47 -> 48574.925
C49: Allocated capex | D49: =D$33*D47 -> 106010.26 | E49: =E$33*E47 -> 135215.48 | F49: =F$33*F47 -> 116402.89 | G49: =G$33*G47 -> 90794.253 | H49: =H$33*H47 -> 70994.122
C50: Allocated trade ΔNWC | D50: =D$38*D47 -> 1569.0187 | E50: =E$38*E47 -> 4747.5697 | F50: =F$38*F47 -> 4528.2327 | G50: =G$38*G47 -> 4345.8024 | H50: =H$38*H47 -> 4071.6312
C51: Allocated unlevered cash flow | D51: =D19*(1-Assumptions!$D$13)+D48-D49-D50 -> -3125.9737 | E51: =E19*(1-Assumptions!$D$13)+E48-E49-E50 -> -14153.864 | F51: =F19*(1-Assumptions!$D$13)+F48-F49-F50 -> 26512.538 | G51: =G19*(1-Assumptions!$D$13)+G48-G49-G50 -> 67591.183 | H51: =H19*(1-Assumptions!$D$13)+H48-H49-H50 -> 99056.672
C53: YouTube ads cash-flow allocation
C54: Revenue allocation weight | D54: =D9/SUM(D$8:D$13) -> 0.091681621 | E54: =E9/SUM(E$8:E$13) -> 0.086111758 | F54: =F9/SUM(F$8:F$13) -> 0.082197987 | G54: =G9/SUM(G$8:G$13) -> 0.07916555 | H54: =H9/SUM(H$8:H$13) -> 0.076887537
C55: Allocated D&A | D55: =D$32*D54 -> 3177.2255 | E55: =E$32*E54 -> 5084.3206 | F55: =F$32*F54 -> 6772.3151 | G55: =G$32*G54 -> 8070.3422 | H55: =H$32*H54 -> 8796.6729
...

Sheet DCF
C2: DCF
C4: Case selected | D4: =CHOOSE(Assumptions!$D$4,"Base","Bull","Bear") -> Base
C6: Common equity market value | D6: =Assumptions!D7*Historicals!H47 -> 4165415.7
C7: Debt market value proxy | D7: =SUM(Historicals!H45:H46) -> 96586
C8: Preferred market value proxy | D8: =Historicals!H48*Historicals!H49 -> 19250
C9: CAPM cost of common equity | D9: =Assumptions!D9+Assumptions!D10*Assumptions!D11 -> 0.099
C10: After-tax debt cost | D10: =Assumptions!D12*(1-Assumptions!D13) -> 0.0384
C11: Preferred cost | D11: =Assumptions!D20 -> 0.0625
C12: Common equity weight | D12: =D6/SUM(D6:D8) -> 0.97294343
C13: Debt weight | D13: =D7/SUM(D6:D8) -> 0.022560225
C14: Preferred weight | D14: =D8/SUM(D6:D8) -> 0.0044963486
C15: WACC | D15: =SUMPRODUCT(D9:D11,D12:D14) -> 0.097468734
C17: Cash-flow discounting | D17: 2026 stub | E17: 2027E | F17: 2028E | G17: 2029E | H17: 2030E
C18: Period end (exclusive) | D18: 46388 | E18: 46753 | F18: 47119 | G18: 47484 | H18: 47849
C19: Period start | D19: =Assumptions!D6 -> 46312 | E19: =DATE(YEAR(E18)-1,1,1) -> 46388 | F19: =DATE(YEAR(F18)-1,1,1) -> 46753 | G19: =DATE(YEAR(G18)-1,1,1) -> 47119 | H19: =DATE(YEAR(H18)-1,1,1) -> 47484
C20: Remaining years | D20: =(D18-D19)/365 -> 0.20821918 | E20: =(E18-E19)/365 -> 1 | F20: =(F18-F19)/365 -> 1.0027397 | G20: =(G18-G19)/365 -> 1 | H20: =(H18-H19)/365 -> 1
C21: Midpoint discount time | D21: =((D18+D19)/2-Assumptions!D6)/365 -> 0.10410959 | E21: =((E18+E19)/2-Assumptions!D6)/365 -> 0.70821918 | F21: =((F18+F19)/2-Assumptions!D6)/365 -> 1.709589 | G21: =((G18+G19)/2-Assumptions!D6)/365 -> 2.7109589 | H21: =((H18+H19)/2-Assumptions!D6)/365 -> 3.7109589
C22: Full-year forecast FCF | D22: =Projections!D40 -> -37533.433 | E22: =Projections!E40 -> -68108.003 | F22: =Projections!F40 -> 12831.95 | G22: =Projections!G40 -> 107438.88 | H22: =Projections!H40 -> 186743.39
C23: Cash flow valued | D23: =Projections!D99*(D18-D19)/(D18-DATE(2026,7,1)) -> -12487.227 | E23: =E22 -> -68108.003 | F23: =F22 -> 12831.95 | G23: =G22 -> 107438.88 | H23: =H22 -> 186743.39
C24: Discount factor | D24: =1/(1+$D$15)^D21 -> 0.99036387 | E24: =1/(1+$D$15)^E21 -> 0.9362536 | F24: =1/(1+$D$15)^F21 -> 0.85299407 | G24: =1/(1+$D$15)^G21 -> 0.77713868 | H24: =1/(1+$D$15)^H21 -> 0.7081192
C25: Present value of cash flow | D25: =D23*D24 -> -12366.898 | E25: =E23*E24 -> -63766.363 | F25: =F23*F24 -> 10945.577 | G25: =G23*G24 -> 83494.911 | H25: =H23*H24 -> 132236.58
C29: 2031 revenue | D29: =Projections!H15*(1+Assumptions!D14) -> 906476.12
C30: 2031 NOPAT | D30: =Projections!H30*(1+Assumptions!D14) -> 256611.96
C31: 2031 D&A | D31: =Projections!H32*(1+Assumptions!D14) -> 117841.9
C32: 2031 normalized capex | D32: =D31*Assumptions!D15 -> 135518.18
C33: 2031 change in trade NWC | D33: =Projections!H36*Assumptions!D14 -> 2640.2217
C34: Normalized terminal FCF | D34: =D30+D31-D32-D33 -> 236295.45
C35: Terminal value at end 2030 | D35: =D34/(D15-Assumptions!D14) -> 3502295.7
C36: Terminal discount time | D36: =(H18-Assumptions!D6)/365 -> 4.2109589
C37: Present value of terminal value | D37: =D35/(1+D15)^D36 -> 2367353.4
C38: Present value of explicit FCF | D38: =SUM(D25:H25) -> 150543.8
C39: Enterprise value | D39: =SUM(D37:D38) -> 2517897.2
C40: Terminal PV / enterprise value | D40: =D37/D39 -> 0.9402105
C42: Cash and marketable securities | D42: =Historicals!H42 -> 242474
C43: Debt carrying value deduction | D43: =-SUM(Historicals!H43:H44) -> -100164
C44: Preferred preference deduction | D44: =-D8 -> -19250
C45: Recognized non-marketable stakes | D45: =Historicals!H50*Assumptions!D16 -> 0
C46: Deferred tax liability deduction | D46: =-Historicals!H51 -> -22819
C47: Accrued legal claims deduction | D47: =-Historicals!H52 -> -17400
C48: Net equity bridge adjustment | D48: =SUM(D42:D47) -> 82841
...

Sheet Sensitivity
C2: Sensitivity
C4: Case selected | D4: =CHOOSE(Assumptions!$D$4,"Base","Bull","Bear") -> Base
C6: WACC rows and perpetual growth columns. Same selected operating case; normalized terminal capex in every cell.
C9: WACC / terminal growth | D9: =Assumptions!D14+(0-2)*Assumptions!D22 -> 0.02 | E9: =Assumptions!D14+(1-2)*Assumptions!D22 -> 0.025 | F9: =Assumptions!D14+(2-2)*Assumptions!D22 -> 0.03 | G9: =Assumptions!D14+(3-2)*Assumptions!D22 -> 0.035 | H9: =Assumptions!D14+(4-2)*Assumptions!D22 -> 0.04
C10: =DCF!D15+(0-3)*Assumptions!D21 -> 0.082468734 | D10: =(SUMPRODUCT(DCF!$D$23:$H$23,1/(1+$C10)^DCF!$D$21:$H$21)+((Projections!$H$30+Projections!$H$32*(1-Assumptions!$D$15))*(1+D$9)-Projections!$H$36*D$9)/($C10-D$9)/(1+$C10)^DCF!$D$36+DCF!$D$48)/DCF!$D$50 -> 240.06418 | E10: =(SUMPRODUCT(DCF!$D$23:$H$23,1/(1+$C10)^DCF!$D$21:$H$21)+((Projections!$H$30+Projections!$H$32*(1-Assumptions!$D$15))*(1+E$9)-Projections!$H$36*E$9)/($C10-E$9)/(1+$C10)^DCF!$D$36+DCF!$D$48)/DCF!$D$50 -> 259.95483 | F10: =(SUMPRODUCT(DCF!$D$23:$H$23,1/(1+$C10)^DCF!$D$21:$H$21)+((Projections!$H$30+Projections!$H$32*(1-Assumptions!$D$15))*(1+F$9)-Projections!$H$36*F$9)/($C10-F$9)/(1+$C10)^DCF!$D$36+DCF!$D$48)/DCF!$D$50 -> 283.63644 | G10: =(SUMPRODUCT(DCF!$D$23:$H$23,1/(1+$C10)^DCF!$D$21:$H$21)+((Projections!$H$30+Projections!$H$32*(1-Assumptions!$D$15))*(1+G$9)-Projections!$H$36*G$9)/($C10-G$9)/(1+$C10)^DCF!$D$36+DCF!$D$48)/DCF!$D$50 -> 312.30694 | H10: =(SUMPRODUCT(DCF!$D$23:$H$23,1/(1+$C10)^DCF!$D$21:$H$21)+((Projections!$H$30+Projections!$H$32*(1-Assumptions!$D$15))*(1+H$9)-Projections!$H$36*H$9)/($C10-H$9)/(1+$C10)^DCF!$D$36+DCF!$D$48)/DCF!$D$50 -> 347.7284
C11: =DCF!D15+(1-3)*Assumptions!D21 -> 0.087468734 | D11: =(SUMPRODUCT(DCF!$D$23:$H$23,1/(1+$C11)^DCF!$D$21:$H$21)+((Projections!$H$30+Projections!$H$32*(1-Assumptions!$D$15))*(1+D$9)-Projections!$H$36*D$9)/($C11-D$9)/(1+$C11)^DCF!$D$36+DCF!$D$48)/DCF!$D$50 -> 219.55792 | E11: =(SUMPRODUCT(DCF!$D$23:$H$23,1/(1+$C11)^DCF!$D$21:$H$21)+((Projections!$H$30+Projections!$H$32*(1-Assumptions!$D$15))*(1+E$9)-Projections!$H$36*E$9)/($C11-E$9)/(1+$C11)^DCF!$D$36+DCF!$D$48)/DCF!$D$50 -> 236.22388 | F11: =(SUMPRODUCT(DCF!$D$23:$H$23,1/(1+$C11)^DCF!$D$21:$H$21)+((Projections!$H$30+Projections!$H$32*(1-Assumptions!$D$15))*(1+F$9)-Projections!$H$36*F$9)/($C11-F$9)/(1+$C11)^DCF!$D$36+DCF!$D$48)/DCF!$D$50 -> 255.78985 | G11: =(SUMPRODUCT(DCF!$D$23:$H$23,1/(1+$C11)^DCF!$D$21:$H$21)+((Projections!$H$30+Projections!$H$32*(1-Assumptions!$D$15))*(1+G$9)-Projections!$H$36*G$9)/($C11-G$9)/(1+$C11)^DCF!$D$36+DCF!$D$48)/DCF!$D$50 -> 279.08489 | H11: =(SUMPRODUCT(DCF!$D$23:$H$23,1/(1+$C11)^DCF!$D$21:$H$21)+((Projections!$H$30+Projections!$H$32*(1-Assumptions!$D$15))*(1+H$9)-Projections!$H$36*H$9)/($C11-H$9)/(1+$C11)^DCF!$D$36+DCF!$D$48)/DCF!$D$50 -> 307.28738
C12: =DCF!D15+(2-3)*Assumptions!D21 -> 0.092468734 | D12: =(SUMPRODUCT(DCF!$D$23:$H$23,1/(1+$C12)^DCF!$D$21:$H$21)+((Projections!$H$30+Projections!$H$32*(1-Assumptions!$D$15))*(1+D$9)-Projections!$H$36*D$9)/($C12-D$9)/(1+$C12)^DCF!$D$36+DCF!$D$48)/DCF!$D$50 -> 201.93594 | E12: =(SUMPRODUCT(DCF!$D$23:$H$23,1/(1+$C12)^DCF!$D$21:$H$21)+((Projections!$H$30+Projections!$H$32*(1-Assumptions!$D$15))*(1+E$9)-Projections!$H$36*E$9)/($C12-E$9)/(1+$C12)^DCF!$D$36+DCF!$D$48)/DCF!$D$50 -> 216.06879 | F12: =(SUMPRODUCT(DCF!$D$23:$H$23,1/(1+$C12)^DCF!$D$21:$H$21)+((Projections!$H$30+Projections!$H$32*(1-Assumptions!$D$15))*(1+F$9)-Projections!$H$36*F$9)/($C12-F$9)/(1+$C12)^DCF!$D$36+DCF!$D$48)/DCF!$D$50 -> 232.46402 | G12: =(SUMPRODUCT(DCF!$D$23:$H$23,1/(1+$C12)^DCF!$D$21:$H$21)+((Projections!$H$30+Projections!$H$32*(1-Assumptions!$D$15))*(1+G$9)-Projections!$H$36*G$9)/($C12-G$9)/(1+$C12)^DCF!$D$36+DCF!$D$48)/DCF!$D$50 -> 251.71215 | H12: =(SUMPRODUCT(DCF!$D$23:$H$23,1/(1+$C12)^DCF!$D$21:$H$21)+((Projections!$H$30+Projections!$H$32*(1-Assumptions!$D$15))*(1+H$9)-Projections!$H$36*H$9)/($C12-H$9)/(1+$C12)^DCF!$D$36+DCF!$D$48)/DCF!$D$50 -> 274.62877
C13: =DCF!D15+(3-3)*Assumptions!D21 -> 0.097468734 | D13: =(SUMPRODUCT(DCF!$D$23:$H$23,1/(1+$C13)^DCF!$D$21:$H$21)+((Projections!$H$30+Projections!$H$32*(1-Assumptions!$D$15))*(1+D$9)-Projections!$H$36*D$9)/($C13-D$9)/(1+$C13)^DCF!$D$36+DCF!$D$48)/DCF!$D$50 -> 186.63844 | E13: =(SUMPRODUCT(DCF!$D$23:$H$23,1/(1+$C13)^DCF!$D$21:$H$21)+((Projections!$H$30+Projections!$H$32*(1-Assumptions!$D$15))*(1+E$9)-Projections!$H$36*E$9)/($C13-E$9)/(1+$C13)^DCF!$D$36+DCF!$D$48)/DCF!$D$50 -> 198.74798 | F13: =(SUMPRODUCT(DCF!$D$23:$H$23,1/(1+$C13)^DCF!$D$21:$H$21)+((Projections!$H$30+Projections!$H$32*(1-Assumptions!$D$15))*(1+F$9)-Projections!$H$36*F$9)/($C13-F$9)/(1+$C13)^DCF!$D$36+DCF!$D$48)/DCF!$D$50 -> 212.65235 | G13: =(SUMPRODUCT(DCF!$D$23:$H$23,1/(1+$C13)^DCF!$D$21:$H$21)+((Projections!$H$30+Projections!$H$32*(1-Assumptions!$D$15))*(1+G$9)-Projections!$H$36*G$9)/($C13-G$9)/(1+$C13)^DCF!$D$36+DCF!$D$48)/DCF!$D$50 -> 228.78253 | H13: =(SUMPRODUCT(DCF!$D$23:$H$23,1/(1+$C13)^DCF!$D$21:$H$21)+((Projections!$H$30+Projections!$H$32*(1-Assumptions!$D$15))*(1+H$9)-Projections!$H$36*H$9)/($C13-H$9)/(1+$C13)^DCF!$D$36+DCF!$D$48)/DCF!$D$50 -> 247.71949
C14: =DCF!D15+(4-3)*Assumptions!D21 -> 0.10246873 | D14: =(SUMPRODUCT(DCF!$D$23:$H$23,1/(1+$C14)^DCF!$D$21:$H$21)+((Projections!$H$30+Projections!$H$32*(1-Assumptions!$D$15))*(1+D$9)-Projections!$H$36*D$9)/($C14-D$9)/(1+$C14)^DCF!$D$36+DCF!$D$48)/DCF!$D$50 -> 173.24142 | E14: =(SUMPRODUCT(DCF!$D$23:$H$23,1/(1+$C14)^DCF!$D$21:$H$21)+((Projections!$H$30+Projections!$H$32*(1-Assumptions!$D$15))*(1+E$9)-Projections!$H$36*E$9)/($C14-E$9)/(1+$C14)^DCF!$D$36+DCF!$D$48)/DCF!$D$50 -> 183.71138 | F14: =(SUMPRODUCT(DCF!$D$23:$H$23,1/(1+$C14)^DCF!$D$21:$H$21)+((Projections!$H$30+Projections!$H$32*(1-Assumptions!$D$15))*(1+F$9)-Projections!$H$36*F$9)/($C14-F$9)/(1+$C14)^DCF!$D$36+DCF!$D$48)/DCF!$D$50 -> 195.62609 | G14: =(SUMPRODUCT(DCF!$D$23:$H$23,1/(1+$C14)^DCF!$D$21:$H$21)+((Projections!$H$30+Projections!$H$32*(1-Assumptions!$D$15))*(1+G$9)-Projections!$H$36*G$9)/($C14-G$9)/(1+$C14)^DCF!$D$36+DCF!$D$48)/DCF!$D$50 -> 209.30675 | H14: =(SUMPRODUCT(DCF!$D$23:$H$23,1/(1+$C14)^DCF!$D$21:$H$21)+((Projections!$H$30+Projections!$H$32*(1-Assumptions!$D$15))*(1+H$9)-Projections!$H$36*H$9)/($C14-H$9)/(1+$C14)^DCF!$D$36+DCF!$D$48)/DCF!$D$50 -> 225.17743
C15: =DCF!D15+(5-3)*Assumptions!D21 -> 0.10746873 | D15: =(SUMPRODUCT(DCF!$D$23:$H$23,1/(1+$C15)^DCF!$D$21:$H$21)+((Projections!$H$30+Projections!$H$32*(1-Assumptions!$D$15))*(1+D$9)-Projections!$H$36*D$9)/($C15-D$9)/(1+$C15)^DCF!$D$36+DCF!$D$48)/DCF!$D$50 -> 161.41787 | E15: =(SUMPRODUCT(DCF!$D$23:$H$23,1/(1+$C15)^DCF!$D$21:$H$21)+((Projections!$H$30+Projections!$H$32*(1-Assumptions!$D$15))*(1+E$9)-Projections!$H$36*E$9)/($C15-E$9)/(1+$C15)^DCF!$D$36+DCF!$D$48)/DCF!$D$50 -> 170.54235 | F15: =(SUMPRODUCT(DCF!$D$23:$H$23,1/(1+$C15)^DCF!$D$21:$H$21)+((Projections!$H$30+Projections!$H$32*(1-Assumptions!$D$15))*(1+F$9)-Projections!$H$36*F$9)/($C15-F$9)/(1+$C15)^DCF!$D$36+DCF!$D$48)/DCF!$D$50 -> 180.84466 | G15: =(SUMPRODUCT(DCF!$D$23:$H$23,1/(1+$C15)^DCF!$D$21:$H$21)+((Projections!$H$30+Projections!$H$32*(1-Assumptions!$D$15))*(1+G$9)-Projections!$H$36*G$9)/($C15-G$9)/(1+$C15)^DCF!$D$36+DCF!$D$48)/DCF!$D$50 -> 192.56859 | H15: =(SUMPRODUCT(DCF!$D$23:$H$23,1/(1+$C15)^DCF!$D$21:$H$21)+((Projections!$H$30+Projections!$H$32*(1-Assumptions!$D$15))*(1+H$9)-Projections!$H$36*H$9)/($C15-H$9)/(1+$C15)^DCF!$D$36+DCF!$D$48)/DCF!$D$50 -> 206.03021
C16: =DCF!D15+(6-3)*Assumptions!D21 -> 0.11246873 | D16: =(SUMPRODUCT(DCF!$D$23:$H$23,1/(1+$C16)^DCF!$D$21:$H$21)+((Projections!$H$30+Projections!$H$32*(1-Assumptions!$D$15))*(1+D$9)-Projections!$H$36*D$9)/($C16-D$9)/(1+$C16)^DCF!$D$36+DCF!$D$48)/DCF!$D$50 -> 150.91152 | E16: =(SUMPRODUCT(DCF!$D$23:$H$23,1/(1+$C16)^DCF!$D$21:$H$21)+((Projections!$H$30+Projections!$H$32*(1-Assumptions!$D$15))*(1+E$9)-Projections!$H$36*E$9)/($C16-E$9)/(1+$C16)^DCF!$D$36+DCF!$D$48)/DCF!$D$50 -> 158.91956 | F16: =(SUMPRODUCT(DCF!$D$23:$H$23,1/(1+$C16)^DCF!$D$21:$H$21)+((Projections!$H$30+Projections!$H$32*(1-Assumptions!$D$15))*(1+F$9)-Projections!$H$36*F$9)/($C16-F$9)/(1+$C16)^DCF!$D$36+DCF!$D$48)/DCF!$D$50 -> 167.89864 | G16: =(SUMPRODUCT(DCF!$D$23:$H$23,1/(1+$C16)^DCF!$D$21:$H$21)+((Projections!$H$30+Projections!$H$32*(1-Assumptions!$D$15))*(1+G$9)-Projections!$H$36*G$9)/($C16-G$9)/(1+$C16)^DCF!$D$36+DCF!$D$48)/DCF!$D$50 -> 178.03678 | H16: =(SUMPRODUCT(DCF!$D$23:$H$23,1/(1+$C16)^DCF!$D$21:$H$21)+((Projections!$H$30+Projections!$H$32*(1-Assumptions!$D$15))*(1+H$9)-Projections!$H$36*H$9)/($C16-H$9)/(1+$C16)^DCF!$D$36+DCF!$D$48)/DCF!$D$50 -> 189.57388
C19: Grid center minus DCF | D19: =F13-DCF!D51 -> 0
C21: Price | D21: =Assumptions!D7 -> 340.59
C22: Required terminal FCF at base WACC | D22: =(Assumptions!D7*DCF!D50-DCF!D48-DCF!D38)*(1+DCF!D15)^DCF!D36*(DCF!D15-Assumptions!D14) -> 392472.46
C23: Required / modeled terminal FCF | D23: =D22/DCF!D34 -> 1.6609395

Sheet Multiples
C2: Multiples
C4: Case selected | D4: =CHOOSE(Assumptions!$D$4,"Base","Bull","Bear") -> Base
C6: Peer inputs | D6: GOOGL | E6: MSFT | F6: META | G6: AMZN | J6: Quotes 2026-10-16; financials TTM through 2026-06-30. USD millions.
C8: Closing price | D8: 340.59 | E8: 529.05 | F8: 709.32 | G8: 250 | J8: Q1 / Q2 / Q3 / Q4. Google Finance vendor displays; exchange-direct unavailable.
C9: Common shares, millions | D9: 12230 | E9: 7427 | F9: 2543 | G9: 10783 | J9: S2 all Alphabet classes; S4 Microsoft period end; S5 Meta Q2 basic weighted-average proxy; S7 Amazon period end.
C10: Equity market value proxy | D10: =D8*D9 -> 4165415.7 | E10: =E8*E9 -> 3929254.3 | F10: =F8*F9 -> 1803800.8 | G10: =G8*G9 -> 2695750
C11: Cash & equivalents | D11: 55911 | E11: 20935 | F11: 15462 | G11: 78213 | J11: S2 / S4 / S5 / S7 balance sheets, 2026-06-30.
C12: Marketable securities | D12: 186563 | E12: 55908 | F12: 74798 | G12: 44775 | J12: S2 / S4 / S5 / S7 balance sheets, 2026-06-30.
C13: Debt non-current | D13: 98165 | E13: 31067 | F13: 83664 | G13: 128894 | J13: S2 / S4 / S5 / S9 balance sheets. Excludes leases.
C14: Debt current | D14: 1999 | E14: 9227 | F14: 0 | G14: 3330 | J14: S2 / S4 / S5 no separate current debt disclosed / S9 Note 5.
C15: Preferred liquidation preference | D15: 19250 | E15: 0 | F15: 0 | G15: 0 | J15: S2 mandatory convertible preference; S4 / S5 / S7 no preferred claim reported.
C16: Enterprise value (excludes leases) | D16: =D10+SUM(D13:D15)-SUM(D11:D12) -> 4042355.7 | E16: =E10+SUM(E13:E15)-SUM(E11:E12) -> 3892705.3 | F16: =F10+SUM(F13:F15)-SUM(F11:F12) -> 1797204.8 | G16: =G10+SUM(G13:G15)-SUM(G11:G12) -> 2704986
C20: FY2025 revenue | D20: 402836 | F20: 200966 | G20: 716924 | J20: S1 / S6 / S8 calendar 2025. Microsoft direct TTM input below.
C21: H1 2025 revenue | D21: 186662 | F21: 89830 | G21: 323369 | J21: S2 / S5 / S7, matched prior six months.
C22: H1 2026 revenue | D22: 229692 | F22: 117111 | G22: 382125 | J22: S2 / S5 / S7, six months ended June 30.
C23: TTM revenue | D23: =D20-D21+D22 -> 445866 | E23: =E40 -> 331839 | F23: =F20-F21+F22 -> 228247 | G23: =G20-G21+G22 -> 775680
C25: FY2025 operating income | D25: 129039 | F25: 83276 | G25: 79975 | J25: S1 / S6 / S8.
C26: H1 2025 operating income | D26: 61877 | F26: 37997 | G26: 37576 | J26: S2 / S5 / S7.
C27: H1 2026 operating income | D27: 80466 | F27: 41647 | G27: 51313 | J27: S2 / S5 / S7.
C28: TTM EBIT | D28: =D25-D26+D27 -> 147628 | E28: =E41 -> 155237 | F28: =F25-F26+F27 -> 86926 | G28: =G25-G26+G27 -> 93712
C30: FY2025 common net income | D30: 132170 | F30: 60458 | G30: 77670 | J30: S1 / S6 / S8, GAAP including investment and tax effects.
C31: H1 2025 common net income | D31: 62736 | F31: 34981 | G31: 35291 | J31: S2 / S5 / S7.
C32: H1 2026 common net income | D32: 174685 | F32: 42621 | G32: 92902 | J32: S2 common earnings after preferred dividends / S5 / S7.
C33: TTM common net income | D33: =D30-D31+D32 -> 244119 | E33: =E42 -> 133749 | F33: =F30-F31+F32 -> 68098 | G33: =G30-G31+G32 -> 135281
C35: FY2025 PPE depreciation | D35: 21136 | F35: 18000 | G35: 41860 | J35: X1 / X3 / X4: us-gaap:Depreciation, calendar FY2025.
C36: H1 2025 PPE depreciation | D36: 9485 | F36: 8120 | G36: 18822 | J36: X1 / X3 / X4: us-gaap:Depreciation, six months ended June 30, 2025.
C37: H1 2026 PPE depreciation | D37: 13586 | F37: 11670 | G37: 26703 | J37: X1 / X3 / X4: us-gaap:Depreciation, six months ended June 30, 2026.
C38: TTM PPE depreciation | D38: =D35-D36+D37 -> 25237 | E38: =E43 -> 34300 | F38: =F35-F36+F37 -> 21550 | G38: =G35-G36+G37 -> 49741
C40: Direct TTM revenue | E40: 331839 | J40: S4 year ended June 30, 2026.
C41: Direct TTM EBIT | E41: 155237 | J41: S4 year ended June 30, 2026.
C42: Direct TTM net income | E42: 133749 | J42: S4 GAAP, year ended June 30, 2026.
C43: Direct TTM PPE depreciation | E43: 34300 | J43: X2: us-gaap:Depreciation, July 1, 2025–June 30, 2026. Broad cash-flow addbacks are excluded.
C45: TTM EBITD (reported inputs) | D45: =D28+D38 -> 172865 | E45: =E28+E38 -> 189537 | F45: =F28+F38 -> 108476 | G45: =G28+G38 -> 143453 | J45: EBIT + PPE depreciation only for all. Reported source arithmetic in rows 35–43; bridge and policy in rows 84–95.
C47: P/E, TTM GAAP | D47: =D10/D33 -> 17.063054 | E47: =E10/E33 -> 29.377822 | F47: =F10/F33 -> 26.488307 | G47: =G10/G33 -> 19.927041
C48: Forward P/E (CY2027 adjusted) | D48: =D8/D77 -> 22.33377 | E48: =E8/E77 -> 24.324138 | F48: =F8/F77 -> 20.482818 | G48: =G8/G77 -> 23.923445 | J48: Price / CY2027 adjusted consensus EPS. See rows 72–82 for dated inputs and Microsoft calendarization.
C49: EV / TTM sales | D49: =D16/D23 -> 9.0663018 | E49: =E16/E23 -> 11.730705 | F49: =F16/F23 -> 7.8739469 | G49: =G16/G23 -> 3.4872447
C50: EV / EBITD | D50: =D16/D45 -> 23.384466 | E50: =E16/E45 -> 20.537971 | F50: =F16/F45 -> 16.567764 | G50: =G16/G45 -> 18.856253
C53: Peer valuation spread | D53: Low | E53: Median | F53: High | J53: MSFT, META, AMZN only. GOOGL excluded from peer median.
C54: P/E | D54: =MIN(E47:G47) -> 19.927041 | E54: =MEDIAN(E47:G47) -> 26.488307 | F54: =MAX(E47:G47) -> 29.377822
C55: EV/Sales | D55: =MIN(E49:G49) -> 3.4872447 | E55: =MEDIAN(E49:G49) -> 7.8739469 | F55: =MAX(E49:G49) -> 11.730705
...
